[2023-12-06T10:52:01.340+0700] {processor.py:153} INFO - Started process (PID=12211) to work on /Users/jacky/airflow/dags/my_dag.py
[2023-12-06T10:52:01.341+0700] {processor.py:743} INFO - Processing file /Users/jacky/airflow/dags/my_dag.py for tasks to queue
[2023-12-06T10:52:01.341+0700] {logging_mixin.py:137} INFO - [2023-12-06T10:52:01.341+0700] {dagbag.py:538} INFO - Filling up the DagBag from /Users/jacky/airflow/dags/my_dag.py
[2023-12-06T10:52:01.436+0700] {processor.py:753} INFO - DAG(s) dict_keys(['my_dag']) retrieved from /Users/jacky/airflow/dags/my_dag.py
[2023-12-06T10:52:02.786+0700] {logging_mixin.py:137} INFO - [2023-12-06T10:52:02.786+0700] {manager.py:504} INFO - Created Permission View: can delete on DAG:my_dag
[2023-12-06T10:52:02.800+0700] {logging_mixin.py:137} INFO - [2023-12-06T10:52:02.799+0700] {manager.py:504} INFO - Created Permission View: can read on DAG:my_dag
[2023-12-06T10:52:02.813+0700] {logging_mixin.py:137} INFO - [2023-12-06T10:52:02.813+0700] {manager.py:504} INFO - Created Permission View: can edit on DAG:my_dag
[2023-12-06T10:52:02.814+0700] {logging_mixin.py:137} INFO - [2023-12-06T10:52:02.813+0700] {dag.py:2676} INFO - Sync 1 DAGs
[2023-12-06T10:52:02.829+0700] {logging_mixin.py:137} INFO - [2023-12-06T10:52:02.829+0700] {dag.py:2697} INFO - Creating ORM DAG for my_dag
[2023-12-06T10:52:02.843+0700] {logging_mixin.py:137} INFO - [2023-12-06T10:52:02.843+0700] {dag.py:3423} INFO - Setting next_dagrun for my_dag to 2023-06-06T16:53:00+00:00, run_after=2023-06-06T16:54:00+00:00
[2023-12-06T10:52:02.870+0700] {processor.py:175} INFO - Processing /Users/jacky/airflow/dags/my_dag.py took 1.530 seconds
[2023-12-06T10:53:10.061+0700] {processor.py:153} INFO - Started process (PID=12998) to work on /Users/jacky/airflow/dags/my_dag.py
[2023-12-06T10:53:10.062+0700] {processor.py:743} INFO - Processing file /Users/jacky/airflow/dags/my_dag.py for tasks to queue
[2023-12-06T10:53:10.063+0700] {logging_mixin.py:137} INFO - [2023-12-06T10:53:10.063+0700] {dagbag.py:538} INFO - Filling up the DagBag from /Users/jacky/airflow/dags/my_dag.py
[2023-12-06T10:53:10.153+0700] {processor.py:753} INFO - DAG(s) dict_keys(['my_dag']) retrieved from /Users/jacky/airflow/dags/my_dag.py
[2023-12-06T10:53:11.066+0700] {logging_mixin.py:137} INFO - [2023-12-06T10:53:11.065+0700] {dag.py:2676} INFO - Sync 1 DAGs
[2023-12-06T10:53:11.090+0700] {logging_mixin.py:137} INFO - [2023-12-06T10:53:11.089+0700] {dag.py:3423} INFO - Setting next_dagrun for my_dag to 2023-06-06T16:53:00+00:00, run_after=2023-06-06T16:54:00+00:00
[2023-12-06T10:53:11.117+0700] {processor.py:175} INFO - Processing /Users/jacky/airflow/dags/my_dag.py took 1.057 seconds
[2023-12-06T10:56:00.068+0700] {processor.py:153} INFO - Started process (PID=14750) to work on /Users/jacky/airflow/dags/my_dag.py
[2023-12-06T10:56:00.069+0700] {processor.py:743} INFO - Processing file /Users/jacky/airflow/dags/my_dag.py for tasks to queue
[2023-12-06T10:56:00.070+0700] {logging_mixin.py:137} INFO - [2023-12-06T10:56:00.070+0700] {dagbag.py:538} INFO - Filling up the DagBag from /Users/jacky/airflow/dags/my_dag.py
[2023-12-06T10:56:00.152+0700] {processor.py:753} INFO - DAG(s) dict_keys(['my_dag']) retrieved from /Users/jacky/airflow/dags/my_dag.py
[2023-12-06T10:56:01.034+0700] {logging_mixin.py:137} INFO - [2023-12-06T10:56:01.034+0700] {dag.py:2676} INFO - Sync 1 DAGs
[2023-12-06T10:56:01.055+0700] {logging_mixin.py:137} INFO - [2023-12-06T10:56:01.055+0700] {dag.py:3423} INFO - Setting next_dagrun for my_dag to 2023-06-06T16:53:00+00:00, run_after=2023-06-06T16:54:00+00:00
[2023-12-06T10:56:01.083+0700] {processor.py:175} INFO - Processing /Users/jacky/airflow/dags/my_dag.py took 1.016 seconds
[2023-12-06T10:59:26.801+0700] {processor.py:153} INFO - Started process (PID=16970) to work on /Users/jacky/airflow/dags/my_dag.py
[2023-12-06T10:59:26.803+0700] {processor.py:743} INFO - Processing file /Users/jacky/airflow/dags/my_dag.py for tasks to queue
[2023-12-06T10:59:26.804+0700] {logging_mixin.py:137} INFO - [2023-12-06T10:59:26.803+0700] {dagbag.py:538} INFO - Filling up the DagBag from /Users/jacky/airflow/dags/my_dag.py
[2023-12-06T10:59:26.913+0700] {processor.py:753} INFO - DAG(s) dict_keys(['my_dag']) retrieved from /Users/jacky/airflow/dags/my_dag.py
[2023-12-06T10:59:27.993+0700] {logging_mixin.py:137} INFO - [2023-12-06T10:59:27.993+0700] {dag.py:2676} INFO - Sync 1 DAGs
[2023-12-06T10:59:28.008+0700] {logging_mixin.py:137} INFO - [2023-12-06T10:59:28.008+0700] {dag.py:2697} INFO - Creating ORM DAG for my_dag
[2023-12-06T10:59:28.027+0700] {logging_mixin.py:137} INFO - [2023-12-06T10:59:28.027+0700] {dag.py:3423} INFO - Setting next_dagrun for my_dag to 2023-06-06T16:53:00+00:00, run_after=2023-06-06T16:54:00+00:00
[2023-12-06T10:59:28.051+0700] {processor.py:175} INFO - Processing /Users/jacky/airflow/dags/my_dag.py took 1.251 seconds
[2023-12-06T11:05:27.825+0700] {processor.py:153} INFO - Started process (PID=20863) to work on /Users/jacky/airflow/dags/my_dag.py
[2023-12-06T11:05:27.827+0700] {processor.py:743} INFO - Processing file /Users/jacky/airflow/dags/my_dag.py for tasks to queue
[2023-12-06T11:05:27.828+0700] {logging_mixin.py:137} INFO - [2023-12-06T11:05:27.828+0700] {dagbag.py:538} INFO - Filling up the DagBag from /Users/jacky/airflow/dags/my_dag.py
[2023-12-06T11:05:27.934+0700] {processor.py:753} INFO - DAG(s) dict_keys(['my_dag']) retrieved from /Users/jacky/airflow/dags/my_dag.py
[2023-12-06T11:05:29.125+0700] {logging_mixin.py:137} INFO - [2023-12-06T11:05:29.125+0700] {dag.py:2676} INFO - Sync 1 DAGs
[2023-12-06T11:05:29.149+0700] {logging_mixin.py:137} INFO - [2023-12-06T11:05:29.149+0700] {dag.py:3423} INFO - Setting next_dagrun for my_dag to 2023-12-06T04:03:00+00:00, run_after=2023-12-06T04:04:00+00:00
[2023-12-06T11:05:29.179+0700] {processor.py:175} INFO - Processing /Users/jacky/airflow/dags/my_dag.py took 1.355 seconds
[2023-12-06T11:08:52.193+0700] {processor.py:153} INFO - Started process (PID=23034) to work on /Users/jacky/airflow/dags/my_dag.py
[2023-12-06T11:08:52.195+0700] {processor.py:743} INFO - Processing file /Users/jacky/airflow/dags/my_dag.py for tasks to queue
[2023-12-06T11:08:52.195+0700] {logging_mixin.py:137} INFO - [2023-12-06T11:08:52.195+0700] {dagbag.py:538} INFO - Filling up the DagBag from /Users/jacky/airflow/dags/my_dag.py
[2023-12-06T11:08:52.299+0700] {processor.py:753} INFO - DAG(s) dict_keys(['my_dag']) retrieved from /Users/jacky/airflow/dags/my_dag.py
[2023-12-06T11:08:53.193+0700] {logging_mixin.py:137} INFO - [2023-12-06T11:08:53.193+0700] {dag.py:2676} INFO - Sync 1 DAGs
[2023-12-06T11:08:53.215+0700] {logging_mixin.py:137} INFO - [2023-12-06T11:08:53.215+0700] {dag.py:3423} INFO - Setting next_dagrun for my_dag to 2023-12-06T04:03:00+00:00, run_after=2023-12-06T04:04:00+00:00
[2023-12-06T11:08:53.237+0700] {processor.py:175} INFO - Processing /Users/jacky/airflow/dags/my_dag.py took 1.045 seconds
[2023-12-06T11:12:16.214+0700] {processor.py:153} INFO - Started process (PID=25418) to work on /Users/jacky/airflow/dags/my_dag.py
[2023-12-06T11:12:16.215+0700] {processor.py:743} INFO - Processing file /Users/jacky/airflow/dags/my_dag.py for tasks to queue
[2023-12-06T11:12:16.215+0700] {logging_mixin.py:137} INFO - [2023-12-06T11:12:16.215+0700] {dagbag.py:538} INFO - Filling up the DagBag from /Users/jacky/airflow/dags/my_dag.py
[2023-12-06T11:12:16.300+0700] {processor.py:753} INFO - DAG(s) dict_keys(['my_dag']) retrieved from /Users/jacky/airflow/dags/my_dag.py
[2023-12-06T11:12:17.443+0700] {logging_mixin.py:137} INFO - [2023-12-06T11:12:17.439+0700] {dag.py:2676} INFO - Sync 1 DAGs
[2023-12-06T11:12:17.493+0700] {logging_mixin.py:137} INFO - [2023-12-06T11:12:17.493+0700] {dag.py:3423} INFO - Setting next_dagrun for my_dag to 2023-12-06T04:03:00+00:00, run_after=2023-12-06T04:04:00+00:00
[2023-12-06T11:12:17.566+0700] {processor.py:175} INFO - Processing /Users/jacky/airflow/dags/my_dag.py took 1.353 seconds
[2023-12-06T11:16:46.837+0700] {processor.py:153} INFO - Started process (PID=28331) to work on /Users/jacky/airflow/dags/my_dag.py
[2023-12-06T11:16:46.839+0700] {processor.py:743} INFO - Processing file /Users/jacky/airflow/dags/my_dag.py for tasks to queue
[2023-12-06T11:16:46.839+0700] {logging_mixin.py:137} INFO - [2023-12-06T11:16:46.839+0700] {dagbag.py:538} INFO - Filling up the DagBag from /Users/jacky/airflow/dags/my_dag.py
[2023-12-06T11:16:46.912+0700] {logging_mixin.py:137} INFO - [2023-12-06T11:16:46.912+0700] {dagbag.py:343} ERROR - Failed to import: /Users/jacky/airflow/dags/my_dag.py
Traceback (most recent call last):
  File "/opt/anaconda3/lib/python3.8/site-packages/airflow/models/dagbag.py", line 339, in parse
    loader.exec_module(new_module)
  File "<frozen importlib._bootstrap_external>", line 783, in exec_module
  File "<frozen importlib._bootstrap>", line 219, in _call_with_frames_removed
  File "/Users/jacky/airflow/dags/my_dag.py", line 67, in <module>
    choosing_best_model = BranchPythonOperator(
NameError: name 'BranchPythonOperator' is not defined
[2023-12-06T11:16:46.913+0700] {processor.py:755} WARNING - No viable dags retrieved from /Users/jacky/airflow/dags/my_dag.py
[2023-12-06T11:16:48.091+0700] {processor.py:175} INFO - Processing /Users/jacky/airflow/dags/my_dag.py took 1.255 seconds
[2023-12-06T11:19:48.697+0700] {processor.py:153} INFO - Started process (PID=30295) to work on /Users/jacky/airflow/dags/my_dag.py
[2023-12-06T11:19:48.699+0700] {processor.py:743} INFO - Processing file /Users/jacky/airflow/dags/my_dag.py for tasks to queue
[2023-12-06T11:19:48.700+0700] {logging_mixin.py:137} INFO - [2023-12-06T11:19:48.700+0700] {dagbag.py:538} INFO - Filling up the DagBag from /Users/jacky/airflow/dags/my_dag.py
[2023-12-06T11:19:48.775+0700] {logging_mixin.py:137} INFO - [2023-12-06T11:19:48.772+0700] {dagbag.py:343} ERROR - Failed to import: /Users/jacky/airflow/dags/my_dag.py
Traceback (most recent call last):
  File "/opt/anaconda3/lib/python3.8/site-packages/airflow/models/dagbag.py", line 339, in parse
    loader.exec_module(new_module)
  File "<frozen importlib._bootstrap_external>", line 783, in exec_module
  File "<frozen importlib._bootstrap>", line 219, in _call_with_frames_removed
  File "/Users/jacky/airflow/dags/my_dag.py", line 67, in <module>
    choosing_best_model = BranchPythonOperator(
NameError: name 'BranchPythonOperator' is not defined
[2023-12-06T11:19:48.775+0700] {processor.py:755} WARNING - No viable dags retrieved from /Users/jacky/airflow/dags/my_dag.py
[2023-12-06T11:19:49.591+0700] {processor.py:175} INFO - Processing /Users/jacky/airflow/dags/my_dag.py took 0.895 seconds
[2023-12-06T11:22:38.637+0700] {processor.py:153} INFO - Started process (PID=32003) to work on /Users/jacky/airflow/dags/my_dag.py
[2023-12-06T11:22:38.639+0700] {processor.py:743} INFO - Processing file /Users/jacky/airflow/dags/my_dag.py for tasks to queue
[2023-12-06T11:22:38.640+0700] {logging_mixin.py:137} INFO - [2023-12-06T11:22:38.640+0700] {dagbag.py:538} INFO - Filling up the DagBag from /Users/jacky/airflow/dags/my_dag.py
[2023-12-06T11:22:38.667+0700] {logging_mixin.py:137} INFO - [2023-12-06T11:22:38.665+0700] {dagbag.py:343} ERROR - Failed to import: /Users/jacky/airflow/dags/my_dag.py
Traceback (most recent call last):
  File "/opt/anaconda3/lib/python3.8/site-packages/airflow/models/dagbag.py", line 339, in parse
    loader.exec_module(new_module)
  File "<frozen importlib._bootstrap_external>", line 779, in exec_module
  File "<frozen importlib._bootstrap_external>", line 916, in get_code
  File "<frozen importlib._bootstrap_external>", line 846, in source_to_code
  File "<frozen importlib._bootstrap>", line 219, in _call_with_frames_removed
  File "/Users/jacky/airflow/dags/my_dag.py", line 90
    training_model_tasks >> choosing_best_model >> [accurate, inaccurate]
    ^
SyntaxError: invalid syntax
[2023-12-06T11:22:38.667+0700] {processor.py:755} WARNING - No viable dags retrieved from /Users/jacky/airflow/dags/my_dag.py
[2023-12-06T11:22:39.611+0700] {processor.py:175} INFO - Processing /Users/jacky/airflow/dags/my_dag.py took 0.975 seconds
[2023-12-06T11:25:47.549+0700] {processor.py:153} INFO - Started process (PID=34035) to work on /Users/jacky/airflow/dags/my_dag.py
[2023-12-06T11:25:47.551+0700] {processor.py:743} INFO - Processing file /Users/jacky/airflow/dags/my_dag.py for tasks to queue
[2023-12-06T11:25:47.552+0700] {logging_mixin.py:137} INFO - [2023-12-06T11:25:47.552+0700] {dagbag.py:538} INFO - Filling up the DagBag from /Users/jacky/airflow/dags/my_dag.py
[2023-12-06T11:25:47.648+0700] {logging_mixin.py:137} INFO - [2023-12-06T11:25:47.645+0700] {dagbag.py:343} ERROR - Failed to import: /Users/jacky/airflow/dags/my_dag.py
Traceback (most recent call last):
  File "/opt/anaconda3/lib/python3.8/site-packages/airflow/models/dagbag.py", line 339, in parse
    loader.exec_module(new_module)
  File "<frozen importlib._bootstrap_external>", line 783, in exec_module
  File "<frozen importlib._bootstrap>", line 219, in _call_with_frames_removed
  File "/Users/jacky/airflow/dags/my_dag.py", line 58, in <module>
    choosing_best_model = BranchPythonOperator(
NameError: name 'BranchPythonOperator' is not defined
[2023-12-06T11:25:47.649+0700] {processor.py:755} WARNING - No viable dags retrieved from /Users/jacky/airflow/dags/my_dag.py
[2023-12-06T11:25:48.659+0700] {processor.py:175} INFO - Processing /Users/jacky/airflow/dags/my_dag.py took 1.111 seconds
[2023-12-06T11:28:37.814+0700] {processor.py:153} INFO - Started process (PID=35838) to work on /Users/jacky/airflow/dags/my_dag.py
[2023-12-06T11:28:37.816+0700] {processor.py:743} INFO - Processing file /Users/jacky/airflow/dags/my_dag.py for tasks to queue
[2023-12-06T11:28:37.817+0700] {logging_mixin.py:137} INFO - [2023-12-06T11:28:37.817+0700] {dagbag.py:538} INFO - Filling up the DagBag from /Users/jacky/airflow/dags/my_dag.py
[2023-12-06T11:28:38.090+0700] {logging_mixin.py:137} INFO - [2023-12-06T11:28:38.079+0700] {dagbag.py:343} ERROR - Failed to import: /Users/jacky/airflow/dags/my_dag.py
Traceback (most recent call last):
  File "/opt/anaconda3/lib/python3.8/site-packages/airflow/models/dagbag.py", line 339, in parse
    loader.exec_module(new_module)
  File "<frozen importlib._bootstrap_external>", line 783, in exec_module
  File "<frozen importlib._bootstrap>", line 219, in _call_with_frames_removed
  File "/Users/jacky/airflow/dags/my_dag.py", line 85, in <module>
    choosing_best_model = BranchPythonOperator(
  File "/opt/anaconda3/lib/python3.8/site-packages/airflow/models/baseoperator.py", line 411, in apply_defaults
    result = func(self, **kwargs, default_args=default_args)
  File "/opt/anaconda3/lib/python3.8/site-packages/airflow/models/baseoperator.py", line 411, in apply_defaults
    result = func(self, **kwargs, default_args=default_args)
  File "/opt/anaconda3/lib/python3.8/site-packages/airflow/operators/python.py", line 160, in __init__
    super().__init__(**kwargs)
  File "/opt/anaconda3/lib/python3.8/site-packages/airflow/models/baseoperator.py", line 411, in apply_defaults
    result = func(self, **kwargs, default_args=default_args)
  File "/opt/anaconda3/lib/python3.8/site-packages/airflow/models/baseoperator.py", line 777, in __init__
    task_group.add(self)
  File "/opt/anaconda3/lib/python3.8/site-packages/airflow/utils/task_group.py", line 220, in add
    raise DuplicateTaskIdFound(f"{node_type} id '{key}' has already been added to the DAG")
airflow.exceptions.DuplicateTaskIdFound: Task id 'choosing_best_model' has already been added to the DAG
[2023-12-06T11:28:38.091+0700] {processor.py:755} WARNING - No viable dags retrieved from /Users/jacky/airflow/dags/my_dag.py
[2023-12-06T11:28:39.449+0700] {processor.py:175} INFO - Processing /Users/jacky/airflow/dags/my_dag.py took 1.636 seconds
[2023-12-06T11:31:43.213+0700] {processor.py:153} INFO - Started process (PID=37882) to work on /Users/jacky/airflow/dags/my_dag.py
[2023-12-06T11:31:43.215+0700] {processor.py:743} INFO - Processing file /Users/jacky/airflow/dags/my_dag.py for tasks to queue
[2023-12-06T11:31:43.216+0700] {logging_mixin.py:137} INFO - [2023-12-06T11:31:43.215+0700] {dagbag.py:538} INFO - Filling up the DagBag from /Users/jacky/airflow/dags/my_dag.py
[2023-12-06T11:31:43.297+0700] {logging_mixin.py:137} INFO - [2023-12-06T11:31:43.292+0700] {dagbag.py:343} ERROR - Failed to import: /Users/jacky/airflow/dags/my_dag.py
Traceback (most recent call last):
  File "/opt/anaconda3/lib/python3.8/site-packages/airflow/models/dagbag.py", line 339, in parse
    loader.exec_module(new_module)
  File "<frozen importlib._bootstrap_external>", line 783, in exec_module
  File "<frozen importlib._bootstrap>", line 219, in _call_with_frames_removed
  File "/Users/jacky/airflow/dags/my_dag.py", line 90, in <module>
    training_model_tasks >> choosing_best_model >> [accurate, inaccurate]
  File "/opt/anaconda3/lib/python3.8/site-packages/airflow/models/taskmixin.py", line 86, in __rrshift__
    self.__lshift__(other)
  File "/opt/anaconda3/lib/python3.8/site-packages/airflow/models/taskmixin.py", line 76, in __lshift__
    self.set_upstream(other)
  File "/opt/anaconda3/lib/python3.8/site-packages/airflow/models/taskmixin.py", line 238, in set_upstream
    self._set_relatives(task_or_task_list, upstream=True, edge_modifier=edge_modifier)
  File "/opt/anaconda3/lib/python3.8/site-packages/airflow/models/taskmixin.py", line 193, in _set_relatives
    raise AirflowException(
airflow.exceptions.AirflowException: Tried to create relationships between tasks that don't have DAGs yet. Set the DAG for at least one task and try again: [<Task(PythonOperator): choosing_best_model>, <Task(PythonOperator): training_model_A>, <Task(PythonOperator): training_model_B>, <Task(PythonOperator): training_model_C>]
[2023-12-06T11:31:43.297+0700] {processor.py:755} WARNING - No viable dags retrieved from /Users/jacky/airflow/dags/my_dag.py
[2023-12-06T11:31:44.087+0700] {processor.py:175} INFO - Processing /Users/jacky/airflow/dags/my_dag.py took 0.874 seconds
[2023-12-06T11:36:17.515+0700] {processor.py:153} INFO - Started process (PID=40796) to work on /Users/jacky/airflow/dags/my_dag.py
[2023-12-06T11:36:17.517+0700] {processor.py:743} INFO - Processing file /Users/jacky/airflow/dags/my_dag.py for tasks to queue
[2023-12-06T11:36:17.518+0700] {logging_mixin.py:137} INFO - [2023-12-06T11:36:17.518+0700] {dagbag.py:538} INFO - Filling up the DagBag from /Users/jacky/airflow/dags/my_dag.py
[2023-12-06T11:36:17.705+0700] {logging_mixin.py:137} INFO - [2023-12-06T11:36:17.699+0700] {dagbag.py:343} ERROR - Failed to import: /Users/jacky/airflow/dags/my_dag.py
Traceback (most recent call last):
  File "/opt/anaconda3/lib/python3.8/site-packages/airflow/models/dagbag.py", line 339, in parse
    loader.exec_module(new_module)
  File "<frozen importlib._bootstrap_external>", line 783, in exec_module
  File "<frozen importlib._bootstrap>", line 219, in _call_with_frames_removed
  File "/Users/jacky/airflow/dags/my_dag.py", line 90, in <module>
    training_model_tasks >> choosing_best_model >> [accurate, inaccurate]
  File "/opt/anaconda3/lib/python3.8/site-packages/airflow/models/taskmixin.py", line 86, in __rrshift__
    self.__lshift__(other)
  File "/opt/anaconda3/lib/python3.8/site-packages/airflow/models/taskmixin.py", line 76, in __lshift__
    self.set_upstream(other)
  File "/opt/anaconda3/lib/python3.8/site-packages/airflow/models/taskmixin.py", line 238, in set_upstream
    self._set_relatives(task_or_task_list, upstream=True, edge_modifier=edge_modifier)
  File "/opt/anaconda3/lib/python3.8/site-packages/airflow/models/taskmixin.py", line 193, in _set_relatives
    raise AirflowException(
airflow.exceptions.AirflowException: Tried to create relationships between tasks that don't have DAGs yet. Set the DAG for at least one task and try again: [<Task(PythonOperator): choosing_best_model>, <Task(PythonOperator): training_model_A>, <Task(PythonOperator): training_model_B>, <Task(PythonOperator): training_model_C>]
[2023-12-06T11:36:17.705+0700] {processor.py:755} WARNING - No viable dags retrieved from /Users/jacky/airflow/dags/my_dag.py
[2023-12-06T11:36:20.308+0700] {processor.py:175} INFO - Processing /Users/jacky/airflow/dags/my_dag.py took 2.794 seconds
[2023-12-06T11:41:11.409+0700] {processor.py:153} INFO - Started process (PID=43947) to work on /Users/jacky/airflow/dags/my_dag.py
[2023-12-06T11:41:11.411+0700] {processor.py:743} INFO - Processing file /Users/jacky/airflow/dags/my_dag.py for tasks to queue
[2023-12-06T11:41:11.412+0700] {logging_mixin.py:137} INFO - [2023-12-06T11:41:11.412+0700] {dagbag.py:538} INFO - Filling up the DagBag from /Users/jacky/airflow/dags/my_dag.py
[2023-12-06T11:41:11.488+0700] {logging_mixin.py:137} INFO - [2023-12-06T11:41:11.484+0700] {dagbag.py:343} ERROR - Failed to import: /Users/jacky/airflow/dags/my_dag.py
Traceback (most recent call last):
  File "/opt/anaconda3/lib/python3.8/site-packages/airflow/models/dagbag.py", line 339, in parse
    loader.exec_module(new_module)
  File "<frozen importlib._bootstrap_external>", line 783, in exec_module
  File "<frozen importlib._bootstrap>", line 219, in _call_with_frames_removed
  File "/Users/jacky/airflow/dags/my_dag.py", line 90, in <module>
    training_model_tasks >> choosing_best_model >> [accurate, inaccurate]
  File "/opt/anaconda3/lib/python3.8/site-packages/airflow/models/taskmixin.py", line 86, in __rrshift__
    self.__lshift__(other)
  File "/opt/anaconda3/lib/python3.8/site-packages/airflow/models/taskmixin.py", line 76, in __lshift__
    self.set_upstream(other)
  File "/opt/anaconda3/lib/python3.8/site-packages/airflow/models/taskmixin.py", line 238, in set_upstream
    self._set_relatives(task_or_task_list, upstream=True, edge_modifier=edge_modifier)
  File "/opt/anaconda3/lib/python3.8/site-packages/airflow/models/taskmixin.py", line 193, in _set_relatives
    raise AirflowException(
airflow.exceptions.AirflowException: Tried to create relationships between tasks that don't have DAGs yet. Set the DAG for at least one task and try again: [<Task(PythonOperator): choosing_best_model>, <Task(PythonOperator): training_model_A>, <Task(PythonOperator): training_model_B>, <Task(PythonOperator): training_model_C>]
[2023-12-06T11:41:11.488+0700] {processor.py:755} WARNING - No viable dags retrieved from /Users/jacky/airflow/dags/my_dag.py
[2023-12-06T11:41:12.459+0700] {processor.py:175} INFO - Processing /Users/jacky/airflow/dags/my_dag.py took 1.050 seconds
[2023-12-06T11:44:17.863+0700] {processor.py:153} INFO - Started process (PID=45922) to work on /Users/jacky/airflow/dags/my_dag.py
[2023-12-06T11:44:17.868+0700] {processor.py:743} INFO - Processing file /Users/jacky/airflow/dags/my_dag.py for tasks to queue
[2023-12-06T11:44:17.869+0700] {logging_mixin.py:137} INFO - [2023-12-06T11:44:17.869+0700] {dagbag.py:538} INFO - Filling up the DagBag from /Users/jacky/airflow/dags/my_dag.py
[2023-12-06T11:44:18.011+0700] {logging_mixin.py:137} INFO - [2023-12-06T11:44:18.006+0700] {dagbag.py:343} ERROR - Failed to import: /Users/jacky/airflow/dags/my_dag.py
Traceback (most recent call last):
  File "/opt/anaconda3/lib/python3.8/site-packages/airflow/models/dagbag.py", line 339, in parse
    loader.exec_module(new_module)
  File "<frozen importlib._bootstrap_external>", line 783, in exec_module
  File "<frozen importlib._bootstrap>", line 219, in _call_with_frames_removed
  File "/Users/jacky/airflow/dags/my_dag.py", line 90, in <module>
    training_model_tasks >> choosing_best_model >> [accurate, inaccurate]
  File "/opt/anaconda3/lib/python3.8/site-packages/airflow/models/taskmixin.py", line 86, in __rrshift__
    self.__lshift__(other)
  File "/opt/anaconda3/lib/python3.8/site-packages/airflow/models/taskmixin.py", line 76, in __lshift__
    self.set_upstream(other)
  File "/opt/anaconda3/lib/python3.8/site-packages/airflow/models/taskmixin.py", line 238, in set_upstream
    self._set_relatives(task_or_task_list, upstream=True, edge_modifier=edge_modifier)
  File "/opt/anaconda3/lib/python3.8/site-packages/airflow/models/taskmixin.py", line 193, in _set_relatives
    raise AirflowException(
airflow.exceptions.AirflowException: Tried to create relationships between tasks that don't have DAGs yet. Set the DAG for at least one task and try again: [<Task(PythonOperator): choosing_best_model>, <Task(PythonOperator): training_model_A>, <Task(PythonOperator): training_model_B>, <Task(PythonOperator): training_model_C>]
[2023-12-06T11:44:18.011+0700] {processor.py:755} WARNING - No viable dags retrieved from /Users/jacky/airflow/dags/my_dag.py
[2023-12-06T11:44:19.436+0700] {processor.py:175} INFO - Processing /Users/jacky/airflow/dags/my_dag.py took 1.577 seconds
[2023-12-06T11:47:45.785+0700] {processor.py:153} INFO - Started process (PID=48168) to work on /Users/jacky/airflow/dags/my_dag.py
[2023-12-06T11:47:45.787+0700] {processor.py:743} INFO - Processing file /Users/jacky/airflow/dags/my_dag.py for tasks to queue
[2023-12-06T11:47:45.788+0700] {logging_mixin.py:137} INFO - [2023-12-06T11:47:45.788+0700] {dagbag.py:538} INFO - Filling up the DagBag from /Users/jacky/airflow/dags/my_dag.py
[2023-12-06T11:47:45.870+0700] {logging_mixin.py:137} INFO - [2023-12-06T11:47:45.863+0700] {dagbag.py:343} ERROR - Failed to import: /Users/jacky/airflow/dags/my_dag.py
Traceback (most recent call last):
  File "/opt/anaconda3/lib/python3.8/site-packages/airflow/models/dagbag.py", line 339, in parse
    loader.exec_module(new_module)
  File "<frozen importlib._bootstrap_external>", line 783, in exec_module
  File "<frozen importlib._bootstrap>", line 219, in _call_with_frames_removed
  File "/Users/jacky/airflow/dags/my_dag.py", line 90, in <module>
    training_model_tasks >> choosing_best_model >> [accurate, inaccurate]
  File "/opt/anaconda3/lib/python3.8/site-packages/airflow/models/taskmixin.py", line 86, in __rrshift__
    self.__lshift__(other)
  File "/opt/anaconda3/lib/python3.8/site-packages/airflow/models/taskmixin.py", line 76, in __lshift__
    self.set_upstream(other)
  File "/opt/anaconda3/lib/python3.8/site-packages/airflow/models/taskmixin.py", line 238, in set_upstream
    self._set_relatives(task_or_task_list, upstream=True, edge_modifier=edge_modifier)
  File "/opt/anaconda3/lib/python3.8/site-packages/airflow/models/taskmixin.py", line 193, in _set_relatives
    raise AirflowException(
airflow.exceptions.AirflowException: Tried to create relationships between tasks that don't have DAGs yet. Set the DAG for at least one task and try again: [<Task(PythonOperator): choosing_best_model>, <Task(PythonOperator): training_model_A>, <Task(PythonOperator): training_model_B>, <Task(PythonOperator): training_model_C>]
[2023-12-06T11:47:45.871+0700] {processor.py:755} WARNING - No viable dags retrieved from /Users/jacky/airflow/dags/my_dag.py
[2023-12-06T11:47:47.131+0700] {processor.py:175} INFO - Processing /Users/jacky/airflow/dags/my_dag.py took 1.346 seconds
[2023-12-06T11:51:10.948+0700] {processor.py:153} INFO - Started process (PID=50355) to work on /Users/jacky/airflow/dags/my_dag.py
[2023-12-06T11:51:10.950+0700] {processor.py:743} INFO - Processing file /Users/jacky/airflow/dags/my_dag.py for tasks to queue
[2023-12-06T11:51:10.951+0700] {logging_mixin.py:137} INFO - [2023-12-06T11:51:10.951+0700] {dagbag.py:538} INFO - Filling up the DagBag from /Users/jacky/airflow/dags/my_dag.py
[2023-12-06T11:51:11.056+0700] {logging_mixin.py:137} INFO - [2023-12-06T11:51:11.051+0700] {dagbag.py:343} ERROR - Failed to import: /Users/jacky/airflow/dags/my_dag.py
Traceback (most recent call last):
  File "/opt/anaconda3/lib/python3.8/site-packages/airflow/models/dagbag.py", line 339, in parse
    loader.exec_module(new_module)
  File "<frozen importlib._bootstrap_external>", line 783, in exec_module
  File "<frozen importlib._bootstrap>", line 219, in _call_with_frames_removed
  File "/Users/jacky/airflow/dags/my_dag.py", line 90, in <module>
    training_model_tasks >> choosing_best_model >> [accurate, inaccurate]
  File "/opt/anaconda3/lib/python3.8/site-packages/airflow/models/taskmixin.py", line 86, in __rrshift__
    self.__lshift__(other)
  File "/opt/anaconda3/lib/python3.8/site-packages/airflow/models/taskmixin.py", line 76, in __lshift__
    self.set_upstream(other)
  File "/opt/anaconda3/lib/python3.8/site-packages/airflow/models/taskmixin.py", line 238, in set_upstream
    self._set_relatives(task_or_task_list, upstream=True, edge_modifier=edge_modifier)
  File "/opt/anaconda3/lib/python3.8/site-packages/airflow/models/taskmixin.py", line 193, in _set_relatives
    raise AirflowException(
airflow.exceptions.AirflowException: Tried to create relationships between tasks that don't have DAGs yet. Set the DAG for at least one task and try again: [<Task(PythonOperator): choosing_best_model>, <Task(PythonOperator): training_model_A>, <Task(PythonOperator): training_model_B>, <Task(PythonOperator): training_model_C>]
[2023-12-06T11:51:11.057+0700] {processor.py:755} WARNING - No viable dags retrieved from /Users/jacky/airflow/dags/my_dag.py
[2023-12-06T11:51:11.947+0700] {processor.py:175} INFO - Processing /Users/jacky/airflow/dags/my_dag.py took 1.000 seconds
[2023-12-06T11:53:40.688+0700] {processor.py:153} INFO - Started process (PID=52001) to work on /Users/jacky/airflow/dags/my_dag.py
[2023-12-06T11:53:40.690+0700] {processor.py:743} INFO - Processing file /Users/jacky/airflow/dags/my_dag.py for tasks to queue
[2023-12-06T11:53:40.691+0700] {logging_mixin.py:137} INFO - [2023-12-06T11:53:40.691+0700] {dagbag.py:538} INFO - Filling up the DagBag from /Users/jacky/airflow/dags/my_dag.py
[2023-12-06T11:53:40.767+0700] {logging_mixin.py:137} INFO - [2023-12-06T11:53:40.760+0700] {dagbag.py:343} ERROR - Failed to import: /Users/jacky/airflow/dags/my_dag.py
Traceback (most recent call last):
  File "/opt/anaconda3/lib/python3.8/site-packages/airflow/models/dagbag.py", line 339, in parse
    loader.exec_module(new_module)
  File "<frozen importlib._bootstrap_external>", line 783, in exec_module
  File "<frozen importlib._bootstrap>", line 219, in _call_with_frames_removed
  File "/Users/jacky/airflow/dags/my_dag.py", line 90, in <module>
    training_model_tasks >> choosing_best_model >> [accurate, inaccurate]
  File "/opt/anaconda3/lib/python3.8/site-packages/airflow/models/taskmixin.py", line 86, in __rrshift__
    self.__lshift__(other)
  File "/opt/anaconda3/lib/python3.8/site-packages/airflow/models/taskmixin.py", line 76, in __lshift__
    self.set_upstream(other)
  File "/opt/anaconda3/lib/python3.8/site-packages/airflow/models/taskmixin.py", line 238, in set_upstream
    self._set_relatives(task_or_task_list, upstream=True, edge_modifier=edge_modifier)
  File "/opt/anaconda3/lib/python3.8/site-packages/airflow/models/taskmixin.py", line 193, in _set_relatives
    raise AirflowException(
airflow.exceptions.AirflowException: Tried to create relationships between tasks that don't have DAGs yet. Set the DAG for at least one task and try again: [<Task(PythonOperator): choosing_best_model>, <Task(PythonOperator): training_model_A>, <Task(PythonOperator): training_model_B>, <Task(PythonOperator): training_model_C>]
[2023-12-06T11:53:40.768+0700] {processor.py:755} WARNING - No viable dags retrieved from /Users/jacky/airflow/dags/my_dag.py
[2023-12-06T11:53:41.708+0700] {processor.py:175} INFO - Processing /Users/jacky/airflow/dags/my_dag.py took 1.020 seconds
[2023-12-06T11:56:01.848+0700] {processor.py:153} INFO - Started process (PID=53477) to work on /Users/jacky/airflow/dags/my_dag.py
[2023-12-06T11:56:01.850+0700] {processor.py:743} INFO - Processing file /Users/jacky/airflow/dags/my_dag.py for tasks to queue
[2023-12-06T11:56:01.851+0700] {logging_mixin.py:137} INFO - [2023-12-06T11:56:01.850+0700] {dagbag.py:538} INFO - Filling up the DagBag from /Users/jacky/airflow/dags/my_dag.py
[2023-12-06T11:56:01.942+0700] {logging_mixin.py:137} INFO - [2023-12-06T11:56:01.939+0700] {dagbag.py:343} ERROR - Failed to import: /Users/jacky/airflow/dags/my_dag.py
Traceback (most recent call last):
  File "/opt/anaconda3/lib/python3.8/site-packages/airflow/models/dagbag.py", line 339, in parse
    loader.exec_module(new_module)
  File "<frozen importlib._bootstrap_external>", line 783, in exec_module
  File "<frozen importlib._bootstrap>", line 219, in _call_with_frames_removed
  File "/Users/jacky/airflow/dags/my_dag.py", line 90, in <module>
    training_model_tasks >> choosing_best_model >> [accurate, inaccurate]
  File "/opt/anaconda3/lib/python3.8/site-packages/airflow/models/taskmixin.py", line 86, in __rrshift__
    self.__lshift__(other)
  File "/opt/anaconda3/lib/python3.8/site-packages/airflow/models/taskmixin.py", line 76, in __lshift__
    self.set_upstream(other)
  File "/opt/anaconda3/lib/python3.8/site-packages/airflow/models/taskmixin.py", line 238, in set_upstream
    self._set_relatives(task_or_task_list, upstream=True, edge_modifier=edge_modifier)
  File "/opt/anaconda3/lib/python3.8/site-packages/airflow/models/taskmixin.py", line 193, in _set_relatives
    raise AirflowException(
airflow.exceptions.AirflowException: Tried to create relationships between tasks that don't have DAGs yet. Set the DAG for at least one task and try again: [<Task(PythonOperator): choosing_best_model>, <Task(PythonOperator): training_model_A>, <Task(PythonOperator): training_model_B>, <Task(PythonOperator): training_model_C>]
[2023-12-06T11:56:01.943+0700] {processor.py:755} WARNING - No viable dags retrieved from /Users/jacky/airflow/dags/my_dag.py
[2023-12-06T11:56:02.838+0700] {processor.py:175} INFO - Processing /Users/jacky/airflow/dags/my_dag.py took 0.991 seconds
[2023-12-06T11:58:28.402+0700] {processor.py:153} INFO - Started process (PID=55065) to work on /Users/jacky/airflow/dags/my_dag.py
[2023-12-06T11:58:28.404+0700] {processor.py:743} INFO - Processing file /Users/jacky/airflow/dags/my_dag.py for tasks to queue
[2023-12-06T11:58:28.404+0700] {logging_mixin.py:137} INFO - [2023-12-06T11:58:28.404+0700] {dagbag.py:538} INFO - Filling up the DagBag from /Users/jacky/airflow/dags/my_dag.py
[2023-12-06T11:58:28.484+0700] {logging_mixin.py:137} INFO - [2023-12-06T11:58:28.478+0700] {dagbag.py:343} ERROR - Failed to import: /Users/jacky/airflow/dags/my_dag.py
Traceback (most recent call last):
  File "/opt/anaconda3/lib/python3.8/site-packages/airflow/models/dagbag.py", line 339, in parse
    loader.exec_module(new_module)
  File "<frozen importlib._bootstrap_external>", line 783, in exec_module
  File "<frozen importlib._bootstrap>", line 219, in _call_with_frames_removed
  File "/Users/jacky/airflow/dags/my_dag.py", line 90, in <module>
    training_model_tasks >> choosing_best_model >> [accurate, inaccurate]
  File "/opt/anaconda3/lib/python3.8/site-packages/airflow/models/taskmixin.py", line 86, in __rrshift__
    self.__lshift__(other)
  File "/opt/anaconda3/lib/python3.8/site-packages/airflow/models/taskmixin.py", line 76, in __lshift__
    self.set_upstream(other)
  File "/opt/anaconda3/lib/python3.8/site-packages/airflow/models/taskmixin.py", line 238, in set_upstream
    self._set_relatives(task_or_task_list, upstream=True, edge_modifier=edge_modifier)
  File "/opt/anaconda3/lib/python3.8/site-packages/airflow/models/taskmixin.py", line 193, in _set_relatives
    raise AirflowException(
airflow.exceptions.AirflowException: Tried to create relationships between tasks that don't have DAGs yet. Set the DAG for at least one task and try again: [<Task(PythonOperator): choosing_best_model>, <Task(PythonOperator): training_model_A>, <Task(PythonOperator): training_model_B>, <Task(PythonOperator): training_model_C>]
[2023-12-06T11:58:28.485+0700] {processor.py:755} WARNING - No viable dags retrieved from /Users/jacky/airflow/dags/my_dag.py
[2023-12-06T11:58:29.268+0700] {processor.py:175} INFO - Processing /Users/jacky/airflow/dags/my_dag.py took 0.867 seconds
[2023-12-06T12:00:56.236+0700] {processor.py:153} INFO - Started process (PID=56659) to work on /Users/jacky/airflow/dags/my_dag.py
[2023-12-06T12:00:56.238+0700] {processor.py:743} INFO - Processing file /Users/jacky/airflow/dags/my_dag.py for tasks to queue
[2023-12-06T12:00:56.239+0700] {logging_mixin.py:137} INFO - [2023-12-06T12:00:56.239+0700] {dagbag.py:538} INFO - Filling up the DagBag from /Users/jacky/airflow/dags/my_dag.py
[2023-12-06T12:00:56.320+0700] {logging_mixin.py:137} INFO - [2023-12-06T12:00:56.316+0700] {dagbag.py:343} ERROR - Failed to import: /Users/jacky/airflow/dags/my_dag.py
Traceback (most recent call last):
  File "/opt/anaconda3/lib/python3.8/site-packages/airflow/models/dagbag.py", line 339, in parse
    loader.exec_module(new_module)
  File "<frozen importlib._bootstrap_external>", line 783, in exec_module
  File "<frozen importlib._bootstrap>", line 219, in _call_with_frames_removed
  File "/Users/jacky/airflow/dags/my_dag.py", line 90, in <module>
    training_model_tasks >> choosing_best_model >> [accurate, inaccurate]
  File "/opt/anaconda3/lib/python3.8/site-packages/airflow/models/taskmixin.py", line 86, in __rrshift__
    self.__lshift__(other)
  File "/opt/anaconda3/lib/python3.8/site-packages/airflow/models/taskmixin.py", line 76, in __lshift__
    self.set_upstream(other)
  File "/opt/anaconda3/lib/python3.8/site-packages/airflow/models/taskmixin.py", line 238, in set_upstream
    self._set_relatives(task_or_task_list, upstream=True, edge_modifier=edge_modifier)
  File "/opt/anaconda3/lib/python3.8/site-packages/airflow/models/taskmixin.py", line 193, in _set_relatives
    raise AirflowException(
airflow.exceptions.AirflowException: Tried to create relationships between tasks that don't have DAGs yet. Set the DAG for at least one task and try again: [<Task(PythonOperator): choosing_best_model>, <Task(PythonOperator): training_model_A>, <Task(PythonOperator): training_model_B>, <Task(PythonOperator): training_model_C>]
[2023-12-06T12:00:56.321+0700] {processor.py:755} WARNING - No viable dags retrieved from /Users/jacky/airflow/dags/my_dag.py
[2023-12-06T12:00:57.047+0700] {processor.py:175} INFO - Processing /Users/jacky/airflow/dags/my_dag.py took 0.812 seconds
[2023-12-06T12:03:17.408+0700] {processor.py:153} INFO - Started process (PID=58132) to work on /Users/jacky/airflow/dags/my_dag.py
[2023-12-06T12:03:17.409+0700] {processor.py:743} INFO - Processing file /Users/jacky/airflow/dags/my_dag.py for tasks to queue
[2023-12-06T12:03:17.410+0700] {logging_mixin.py:137} INFO - [2023-12-06T12:03:17.410+0700] {dagbag.py:538} INFO - Filling up the DagBag from /Users/jacky/airflow/dags/my_dag.py
[2023-12-06T12:03:17.487+0700] {logging_mixin.py:137} INFO - [2023-12-06T12:03:17.482+0700] {dagbag.py:343} ERROR - Failed to import: /Users/jacky/airflow/dags/my_dag.py
Traceback (most recent call last):
  File "/opt/anaconda3/lib/python3.8/site-packages/airflow/models/dagbag.py", line 339, in parse
    loader.exec_module(new_module)
  File "<frozen importlib._bootstrap_external>", line 783, in exec_module
  File "<frozen importlib._bootstrap>", line 219, in _call_with_frames_removed
  File "/Users/jacky/airflow/dags/my_dag.py", line 90, in <module>
    training_model_tasks >> choosing_best_model >> [accurate, inaccurate]
  File "/opt/anaconda3/lib/python3.8/site-packages/airflow/models/taskmixin.py", line 86, in __rrshift__
    self.__lshift__(other)
  File "/opt/anaconda3/lib/python3.8/site-packages/airflow/models/taskmixin.py", line 76, in __lshift__
    self.set_upstream(other)
  File "/opt/anaconda3/lib/python3.8/site-packages/airflow/models/taskmixin.py", line 238, in set_upstream
    self._set_relatives(task_or_task_list, upstream=True, edge_modifier=edge_modifier)
  File "/opt/anaconda3/lib/python3.8/site-packages/airflow/models/taskmixin.py", line 193, in _set_relatives
    raise AirflowException(
airflow.exceptions.AirflowException: Tried to create relationships between tasks that don't have DAGs yet. Set the DAG for at least one task and try again: [<Task(PythonOperator): choosing_best_model>, <Task(PythonOperator): training_model_A>, <Task(PythonOperator): training_model_B>, <Task(PythonOperator): training_model_C>]
[2023-12-06T12:03:17.487+0700] {processor.py:755} WARNING - No viable dags retrieved from /Users/jacky/airflow/dags/my_dag.py
[2023-12-06T12:03:18.202+0700] {processor.py:175} INFO - Processing /Users/jacky/airflow/dags/my_dag.py took 0.795 seconds
[2023-12-06T15:14:44.732+0700] {processor.py:153} INFO - Started process (PID=61140) to work on /Users/jacky/airflow/dags/my_dag.py
[2023-12-06T15:14:44.734+0700] {processor.py:743} INFO - Processing file /Users/jacky/airflow/dags/my_dag.py for tasks to queue
[2023-12-06T15:14:44.734+0700] {logging_mixin.py:137} INFO - [2023-12-06T15:14:44.734+0700] {dagbag.py:538} INFO - Filling up the DagBag from /Users/jacky/airflow/dags/my_dag.py
[2023-12-06T15:14:44.818+0700] {logging_mixin.py:137} INFO - [2023-12-06T15:14:44.813+0700] {dagbag.py:343} ERROR - Failed to import: /Users/jacky/airflow/dags/my_dag.py
Traceback (most recent call last):
  File "/opt/anaconda3/lib/python3.8/site-packages/airflow/models/dagbag.py", line 339, in parse
    loader.exec_module(new_module)
  File "<frozen importlib._bootstrap_external>", line 783, in exec_module
  File "<frozen importlib._bootstrap>", line 219, in _call_with_frames_removed
  File "/Users/jacky/airflow/dags/my_dag.py", line 90, in <module>
    training_model_tasks >> choosing_best_model >> [accurate, inaccurate]
  File "/opt/anaconda3/lib/python3.8/site-packages/airflow/models/taskmixin.py", line 86, in __rrshift__
    self.__lshift__(other)
  File "/opt/anaconda3/lib/python3.8/site-packages/airflow/models/taskmixin.py", line 76, in __lshift__
    self.set_upstream(other)
  File "/opt/anaconda3/lib/python3.8/site-packages/airflow/models/taskmixin.py", line 238, in set_upstream
    self._set_relatives(task_or_task_list, upstream=True, edge_modifier=edge_modifier)
  File "/opt/anaconda3/lib/python3.8/site-packages/airflow/models/taskmixin.py", line 193, in _set_relatives
    raise AirflowException(
airflow.exceptions.AirflowException: Tried to create relationships between tasks that don't have DAGs yet. Set the DAG for at least one task and try again: [<Task(PythonOperator): choosing_best_model>, <Task(PythonOperator): training_model_A>, <Task(PythonOperator): training_model_B>, <Task(PythonOperator): training_model_C>]
[2023-12-06T15:14:44.818+0700] {processor.py:755} WARNING - No viable dags retrieved from /Users/jacky/airflow/dags/my_dag.py
[2023-12-06T15:14:45.514+0700] {processor.py:175} INFO - Processing /Users/jacky/airflow/dags/my_dag.py took 0.782 seconds
[2023-12-06T15:17:12.809+0700] {processor.py:153} INFO - Started process (PID=62725) to work on /Users/jacky/airflow/dags/my_dag.py
[2023-12-06T15:17:12.811+0700] {processor.py:743} INFO - Processing file /Users/jacky/airflow/dags/my_dag.py for tasks to queue
[2023-12-06T15:17:12.811+0700] {logging_mixin.py:137} INFO - [2023-12-06T15:17:12.811+0700] {dagbag.py:538} INFO - Filling up the DagBag from /Users/jacky/airflow/dags/my_dag.py
[2023-12-06T15:17:12.891+0700] {logging_mixin.py:137} INFO - [2023-12-06T15:17:12.886+0700] {dagbag.py:343} ERROR - Failed to import: /Users/jacky/airflow/dags/my_dag.py
Traceback (most recent call last):
  File "/opt/anaconda3/lib/python3.8/site-packages/airflow/models/dagbag.py", line 339, in parse
    loader.exec_module(new_module)
  File "<frozen importlib._bootstrap_external>", line 783, in exec_module
  File "<frozen importlib._bootstrap>", line 219, in _call_with_frames_removed
  File "/Users/jacky/airflow/dags/my_dag.py", line 90, in <module>
    training_model_tasks >> choosing_best_model >> [accurate, inaccurate]
  File "/opt/anaconda3/lib/python3.8/site-packages/airflow/models/taskmixin.py", line 86, in __rrshift__
    self.__lshift__(other)
  File "/opt/anaconda3/lib/python3.8/site-packages/airflow/models/taskmixin.py", line 76, in __lshift__
    self.set_upstream(other)
  File "/opt/anaconda3/lib/python3.8/site-packages/airflow/models/taskmixin.py", line 238, in set_upstream
    self._set_relatives(task_or_task_list, upstream=True, edge_modifier=edge_modifier)
  File "/opt/anaconda3/lib/python3.8/site-packages/airflow/models/taskmixin.py", line 193, in _set_relatives
    raise AirflowException(
airflow.exceptions.AirflowException: Tried to create relationships between tasks that don't have DAGs yet. Set the DAG for at least one task and try again: [<Task(PythonOperator): choosing_best_model>, <Task(PythonOperator): training_model_A>, <Task(PythonOperator): training_model_B>, <Task(PythonOperator): training_model_C>]
[2023-12-06T15:17:12.892+0700] {processor.py:755} WARNING - No viable dags retrieved from /Users/jacky/airflow/dags/my_dag.py
[2023-12-06T15:17:13.587+0700] {processor.py:175} INFO - Processing /Users/jacky/airflow/dags/my_dag.py took 0.779 seconds
[2023-12-06T15:19:33.227+0700] {processor.py:153} INFO - Started process (PID=64200) to work on /Users/jacky/airflow/dags/my_dag.py
[2023-12-06T15:19:33.228+0700] {processor.py:743} INFO - Processing file /Users/jacky/airflow/dags/my_dag.py for tasks to queue
[2023-12-06T15:19:33.228+0700] {logging_mixin.py:137} INFO - [2023-12-06T15:19:33.228+0700] {dagbag.py:538} INFO - Filling up the DagBag from /Users/jacky/airflow/dags/my_dag.py
[2023-12-06T15:19:33.293+0700] {logging_mixin.py:137} INFO - [2023-12-06T15:19:33.292+0700] {dagbag.py:343} ERROR - Failed to import: /Users/jacky/airflow/dags/my_dag.py
Traceback (most recent call last):
  File "/opt/anaconda3/lib/python3.8/site-packages/airflow/models/dagbag.py", line 339, in parse
    loader.exec_module(new_module)
  File "<frozen importlib._bootstrap_external>", line 783, in exec_module
  File "<frozen importlib._bootstrap>", line 219, in _call_with_frames_removed
  File "/Users/jacky/airflow/dags/my_dag.py", line 90, in <module>
    training_model_tasks >> choosing_best_model >> [accurate, inaccurate]
  File "/opt/anaconda3/lib/python3.8/site-packages/airflow/models/taskmixin.py", line 86, in __rrshift__
    self.__lshift__(other)
  File "/opt/anaconda3/lib/python3.8/site-packages/airflow/models/taskmixin.py", line 76, in __lshift__
    self.set_upstream(other)
  File "/opt/anaconda3/lib/python3.8/site-packages/airflow/models/taskmixin.py", line 238, in set_upstream
    self._set_relatives(task_or_task_list, upstream=True, edge_modifier=edge_modifier)
  File "/opt/anaconda3/lib/python3.8/site-packages/airflow/models/taskmixin.py", line 193, in _set_relatives
    raise AirflowException(
airflow.exceptions.AirflowException: Tried to create relationships between tasks that don't have DAGs yet. Set the DAG for at least one task and try again: [<Task(PythonOperator): choosing_best_model>, <Task(PythonOperator): training_model_A>, <Task(PythonOperator): training_model_B>, <Task(PythonOperator): training_model_C>]
[2023-12-06T15:19:33.293+0700] {processor.py:755} WARNING - No viable dags retrieved from /Users/jacky/airflow/dags/my_dag.py
[2023-12-06T15:19:34.052+0700] {processor.py:175} INFO - Processing /Users/jacky/airflow/dags/my_dag.py took 0.826 seconds
[2023-12-06T15:21:55.928+0700] {processor.py:153} INFO - Started process (PID=65686) to work on /Users/jacky/airflow/dags/my_dag.py
[2023-12-06T15:21:55.930+0700] {processor.py:743} INFO - Processing file /Users/jacky/airflow/dags/my_dag.py for tasks to queue
[2023-12-06T15:21:55.933+0700] {logging_mixin.py:137} INFO - [2023-12-06T15:21:55.932+0700] {dagbag.py:538} INFO - Filling up the DagBag from /Users/jacky/airflow/dags/my_dag.py
[2023-12-06T15:21:56.050+0700] {logging_mixin.py:137} INFO - [2023-12-06T15:21:56.044+0700] {dagbag.py:343} ERROR - Failed to import: /Users/jacky/airflow/dags/my_dag.py
Traceback (most recent call last):
  File "/opt/anaconda3/lib/python3.8/site-packages/airflow/models/dagbag.py", line 339, in parse
    loader.exec_module(new_module)
  File "<frozen importlib._bootstrap_external>", line 783, in exec_module
  File "<frozen importlib._bootstrap>", line 219, in _call_with_frames_removed
  File "/Users/jacky/airflow/dags/my_dag.py", line 90, in <module>
    training_model_tasks >> choosing_best_model >> [accurate, inaccurate]
  File "/opt/anaconda3/lib/python3.8/site-packages/airflow/models/taskmixin.py", line 86, in __rrshift__
    self.__lshift__(other)
  File "/opt/anaconda3/lib/python3.8/site-packages/airflow/models/taskmixin.py", line 76, in __lshift__
    self.set_upstream(other)
  File "/opt/anaconda3/lib/python3.8/site-packages/airflow/models/taskmixin.py", line 238, in set_upstream
    self._set_relatives(task_or_task_list, upstream=True, edge_modifier=edge_modifier)
  File "/opt/anaconda3/lib/python3.8/site-packages/airflow/models/taskmixin.py", line 193, in _set_relatives
    raise AirflowException(
airflow.exceptions.AirflowException: Tried to create relationships between tasks that don't have DAGs yet. Set the DAG for at least one task and try again: [<Task(PythonOperator): choosing_best_model>, <Task(PythonOperator): training_model_A>, <Task(PythonOperator): training_model_B>, <Task(PythonOperator): training_model_C>]
[2023-12-06T15:21:56.050+0700] {processor.py:755} WARNING - No viable dags retrieved from /Users/jacky/airflow/dags/my_dag.py
[2023-12-06T15:21:57.121+0700] {processor.py:175} INFO - Processing /Users/jacky/airflow/dags/my_dag.py took 1.197 seconds
[2023-12-06T15:24:18.976+0700] {processor.py:153} INFO - Started process (PID=67269) to work on /Users/jacky/airflow/dags/my_dag.py
[2023-12-06T15:24:18.977+0700] {processor.py:743} INFO - Processing file /Users/jacky/airflow/dags/my_dag.py for tasks to queue
[2023-12-06T15:24:18.978+0700] {logging_mixin.py:137} INFO - [2023-12-06T15:24:18.978+0700] {dagbag.py:538} INFO - Filling up the DagBag from /Users/jacky/airflow/dags/my_dag.py
[2023-12-06T15:24:19.059+0700] {logging_mixin.py:137} INFO - [2023-12-06T15:24:19.055+0700] {dagbag.py:343} ERROR - Failed to import: /Users/jacky/airflow/dags/my_dag.py
Traceback (most recent call last):
  File "/opt/anaconda3/lib/python3.8/site-packages/airflow/models/dagbag.py", line 339, in parse
    loader.exec_module(new_module)
  File "<frozen importlib._bootstrap_external>", line 783, in exec_module
  File "<frozen importlib._bootstrap>", line 219, in _call_with_frames_removed
  File "/Users/jacky/airflow/dags/my_dag.py", line 90, in <module>
    training_model_tasks >> choosing_best_model >> [accurate, inaccurate]
  File "/opt/anaconda3/lib/python3.8/site-packages/airflow/models/taskmixin.py", line 86, in __rrshift__
    self.__lshift__(other)
  File "/opt/anaconda3/lib/python3.8/site-packages/airflow/models/taskmixin.py", line 76, in __lshift__
    self.set_upstream(other)
  File "/opt/anaconda3/lib/python3.8/site-packages/airflow/models/taskmixin.py", line 238, in set_upstream
    self._set_relatives(task_or_task_list, upstream=True, edge_modifier=edge_modifier)
  File "/opt/anaconda3/lib/python3.8/site-packages/airflow/models/taskmixin.py", line 193, in _set_relatives
    raise AirflowException(
airflow.exceptions.AirflowException: Tried to create relationships between tasks that don't have DAGs yet. Set the DAG for at least one task and try again: [<Task(PythonOperator): choosing_best_model>, <Task(PythonOperator): training_model_A>, <Task(PythonOperator): training_model_B>, <Task(PythonOperator): training_model_C>]
[2023-12-06T15:24:19.059+0700] {processor.py:755} WARNING - No viable dags retrieved from /Users/jacky/airflow/dags/my_dag.py
[2023-12-06T15:24:19.900+0700] {processor.py:175} INFO - Processing /Users/jacky/airflow/dags/my_dag.py took 0.925 seconds
[2023-12-06T15:26:49.661+0700] {processor.py:153} INFO - Started process (PID=68856) to work on /Users/jacky/airflow/dags/my_dag.py
[2023-12-06T15:26:49.663+0700] {processor.py:743} INFO - Processing file /Users/jacky/airflow/dags/my_dag.py for tasks to queue
[2023-12-06T15:26:49.663+0700] {logging_mixin.py:137} INFO - [2023-12-06T15:26:49.663+0700] {dagbag.py:538} INFO - Filling up the DagBag from /Users/jacky/airflow/dags/my_dag.py
[2023-12-06T15:26:49.735+0700] {logging_mixin.py:137} INFO - [2023-12-06T15:26:49.731+0700] {dagbag.py:343} ERROR - Failed to import: /Users/jacky/airflow/dags/my_dag.py
Traceback (most recent call last):
  File "/opt/anaconda3/lib/python3.8/site-packages/airflow/models/dagbag.py", line 339, in parse
    loader.exec_module(new_module)
  File "<frozen importlib._bootstrap_external>", line 783, in exec_module
  File "<frozen importlib._bootstrap>", line 219, in _call_with_frames_removed
  File "/Users/jacky/airflow/dags/my_dag.py", line 90, in <module>
    training_model_tasks >> choosing_best_model >> [accurate, inaccurate]
  File "/opt/anaconda3/lib/python3.8/site-packages/airflow/models/taskmixin.py", line 86, in __rrshift__
    self.__lshift__(other)
  File "/opt/anaconda3/lib/python3.8/site-packages/airflow/models/taskmixin.py", line 76, in __lshift__
    self.set_upstream(other)
  File "/opt/anaconda3/lib/python3.8/site-packages/airflow/models/taskmixin.py", line 238, in set_upstream
    self._set_relatives(task_or_task_list, upstream=True, edge_modifier=edge_modifier)
  File "/opt/anaconda3/lib/python3.8/site-packages/airflow/models/taskmixin.py", line 193, in _set_relatives
    raise AirflowException(
airflow.exceptions.AirflowException: Tried to create relationships between tasks that don't have DAGs yet. Set the DAG for at least one task and try again: [<Task(PythonOperator): choosing_best_model>, <Task(PythonOperator): training_model_A>, <Task(PythonOperator): training_model_B>, <Task(PythonOperator): training_model_C>]
[2023-12-06T15:26:49.736+0700] {processor.py:755} WARNING - No viable dags retrieved from /Users/jacky/airflow/dags/my_dag.py
[2023-12-06T15:26:50.567+0700] {processor.py:175} INFO - Processing /Users/jacky/airflow/dags/my_dag.py took 0.907 seconds
[2023-12-06T15:29:07.983+0700] {processor.py:153} INFO - Started process (PID=70330) to work on /Users/jacky/airflow/dags/my_dag.py
[2023-12-06T15:29:07.984+0700] {processor.py:743} INFO - Processing file /Users/jacky/airflow/dags/my_dag.py for tasks to queue
[2023-12-06T15:29:07.985+0700] {logging_mixin.py:137} INFO - [2023-12-06T15:29:07.985+0700] {dagbag.py:538} INFO - Filling up the DagBag from /Users/jacky/airflow/dags/my_dag.py
[2023-12-06T15:29:08.092+0700] {logging_mixin.py:137} INFO - [2023-12-06T15:29:08.090+0700] {dagbag.py:343} ERROR - Failed to import: /Users/jacky/airflow/dags/my_dag.py
Traceback (most recent call last):
  File "/opt/anaconda3/lib/python3.8/site-packages/airflow/models/dagbag.py", line 339, in parse
    loader.exec_module(new_module)
  File "<frozen importlib._bootstrap_external>", line 783, in exec_module
  File "<frozen importlib._bootstrap>", line 219, in _call_with_frames_removed
  File "/Users/jacky/airflow/dags/my_dag.py", line 90, in <module>
    training_model_tasks >> choosing_best_model >> [accurate, inaccurate]
  File "/opt/anaconda3/lib/python3.8/site-packages/airflow/models/taskmixin.py", line 86, in __rrshift__
    self.__lshift__(other)
  File "/opt/anaconda3/lib/python3.8/site-packages/airflow/models/taskmixin.py", line 76, in __lshift__
    self.set_upstream(other)
  File "/opt/anaconda3/lib/python3.8/site-packages/airflow/models/taskmixin.py", line 238, in set_upstream
    self._set_relatives(task_or_task_list, upstream=True, edge_modifier=edge_modifier)
  File "/opt/anaconda3/lib/python3.8/site-packages/airflow/models/taskmixin.py", line 193, in _set_relatives
    raise AirflowException(
airflow.exceptions.AirflowException: Tried to create relationships between tasks that don't have DAGs yet. Set the DAG for at least one task and try again: [<Task(PythonOperator): choosing_best_model>, <Task(PythonOperator): training_model_A>, <Task(PythonOperator): training_model_B>, <Task(PythonOperator): training_model_C>]
[2023-12-06T15:29:08.092+0700] {processor.py:755} WARNING - No viable dags retrieved from /Users/jacky/airflow/dags/my_dag.py
[2023-12-06T15:29:08.873+0700] {processor.py:175} INFO - Processing /Users/jacky/airflow/dags/my_dag.py took 0.891 seconds
[2023-12-06T15:31:37.413+0700] {processor.py:153} INFO - Started process (PID=71919) to work on /Users/jacky/airflow/dags/my_dag.py
[2023-12-06T15:31:37.415+0700] {processor.py:743} INFO - Processing file /Users/jacky/airflow/dags/my_dag.py for tasks to queue
[2023-12-06T15:31:37.416+0700] {logging_mixin.py:137} INFO - [2023-12-06T15:31:37.415+0700] {dagbag.py:538} INFO - Filling up the DagBag from /Users/jacky/airflow/dags/my_dag.py
[2023-12-06T15:31:37.508+0700] {logging_mixin.py:137} INFO - [2023-12-06T15:31:37.503+0700] {dagbag.py:343} ERROR - Failed to import: /Users/jacky/airflow/dags/my_dag.py
Traceback (most recent call last):
  File "/opt/anaconda3/lib/python3.8/site-packages/airflow/models/dagbag.py", line 339, in parse
    loader.exec_module(new_module)
  File "<frozen importlib._bootstrap_external>", line 783, in exec_module
  File "<frozen importlib._bootstrap>", line 219, in _call_with_frames_removed
  File "/Users/jacky/airflow/dags/my_dag.py", line 90, in <module>
    training_model_tasks >> choosing_best_model >> [accurate, inaccurate]
  File "/opt/anaconda3/lib/python3.8/site-packages/airflow/models/taskmixin.py", line 86, in __rrshift__
    self.__lshift__(other)
  File "/opt/anaconda3/lib/python3.8/site-packages/airflow/models/taskmixin.py", line 76, in __lshift__
    self.set_upstream(other)
  File "/opt/anaconda3/lib/python3.8/site-packages/airflow/models/taskmixin.py", line 238, in set_upstream
    self._set_relatives(task_or_task_list, upstream=True, edge_modifier=edge_modifier)
  File "/opt/anaconda3/lib/python3.8/site-packages/airflow/models/taskmixin.py", line 193, in _set_relatives
    raise AirflowException(
airflow.exceptions.AirflowException: Tried to create relationships between tasks that don't have DAGs yet. Set the DAG for at least one task and try again: [<Task(PythonOperator): choosing_best_model>, <Task(PythonOperator): training_model_A>, <Task(PythonOperator): training_model_B>, <Task(PythonOperator): training_model_C>]
[2023-12-06T15:31:37.508+0700] {processor.py:755} WARNING - No viable dags retrieved from /Users/jacky/airflow/dags/my_dag.py
[2023-12-06T15:31:38.502+0700] {processor.py:175} INFO - Processing /Users/jacky/airflow/dags/my_dag.py took 1.090 seconds
[2023-12-06T15:34:07.322+0700] {processor.py:153} INFO - Started process (PID=73636) to work on /Users/jacky/airflow/dags/my_dag.py
[2023-12-06T15:34:07.324+0700] {processor.py:743} INFO - Processing file /Users/jacky/airflow/dags/my_dag.py for tasks to queue
[2023-12-06T15:34:07.325+0700] {logging_mixin.py:137} INFO - [2023-12-06T15:34:07.325+0700] {dagbag.py:538} INFO - Filling up the DagBag from /Users/jacky/airflow/dags/my_dag.py
[2023-12-06T15:34:07.393+0700] {logging_mixin.py:137} INFO - [2023-12-06T15:34:07.387+0700] {dagbag.py:343} ERROR - Failed to import: /Users/jacky/airflow/dags/my_dag.py
Traceback (most recent call last):
  File "/opt/anaconda3/lib/python3.8/site-packages/airflow/models/dagbag.py", line 339, in parse
    loader.exec_module(new_module)
  File "<frozen importlib._bootstrap_external>", line 783, in exec_module
  File "<frozen importlib._bootstrap>", line 219, in _call_with_frames_removed
  File "/Users/jacky/airflow/dags/my_dag.py", line 90, in <module>
    training_model_tasks >> choosing_best_model >> [accurate, inaccurate]
  File "/opt/anaconda3/lib/python3.8/site-packages/airflow/models/taskmixin.py", line 86, in __rrshift__
    self.__lshift__(other)
  File "/opt/anaconda3/lib/python3.8/site-packages/airflow/models/taskmixin.py", line 76, in __lshift__
    self.set_upstream(other)
  File "/opt/anaconda3/lib/python3.8/site-packages/airflow/models/taskmixin.py", line 238, in set_upstream
    self._set_relatives(task_or_task_list, upstream=True, edge_modifier=edge_modifier)
  File "/opt/anaconda3/lib/python3.8/site-packages/airflow/models/taskmixin.py", line 193, in _set_relatives
    raise AirflowException(
airflow.exceptions.AirflowException: Tried to create relationships between tasks that don't have DAGs yet. Set the DAG for at least one task and try again: [<Task(PythonOperator): choosing_best_model>, <Task(PythonOperator): training_model_A>, <Task(PythonOperator): training_model_B>, <Task(PythonOperator): training_model_C>]
[2023-12-06T15:34:07.393+0700] {processor.py:755} WARNING - No viable dags retrieved from /Users/jacky/airflow/dags/my_dag.py
[2023-12-06T15:34:08.108+0700] {processor.py:175} INFO - Processing /Users/jacky/airflow/dags/my_dag.py took 0.786 seconds
[2023-12-06T15:36:28.380+0700] {processor.py:153} INFO - Started process (PID=75130) to work on /Users/jacky/airflow/dags/my_dag.py
[2023-12-06T15:36:28.382+0700] {processor.py:743} INFO - Processing file /Users/jacky/airflow/dags/my_dag.py for tasks to queue
[2023-12-06T15:36:28.383+0700] {logging_mixin.py:137} INFO - [2023-12-06T15:36:28.383+0700] {dagbag.py:538} INFO - Filling up the DagBag from /Users/jacky/airflow/dags/my_dag.py
[2023-12-06T15:36:28.456+0700] {logging_mixin.py:137} INFO - [2023-12-06T15:36:28.450+0700] {dagbag.py:343} ERROR - Failed to import: /Users/jacky/airflow/dags/my_dag.py
Traceback (most recent call last):
  File "/opt/anaconda3/lib/python3.8/site-packages/airflow/models/dagbag.py", line 339, in parse
    loader.exec_module(new_module)
  File "<frozen importlib._bootstrap_external>", line 783, in exec_module
  File "<frozen importlib._bootstrap>", line 219, in _call_with_frames_removed
  File "/Users/jacky/airflow/dags/my_dag.py", line 90, in <module>
    training_model_tasks >> choosing_best_model >> [accurate, inaccurate]
  File "/opt/anaconda3/lib/python3.8/site-packages/airflow/models/taskmixin.py", line 86, in __rrshift__
    self.__lshift__(other)
  File "/opt/anaconda3/lib/python3.8/site-packages/airflow/models/taskmixin.py", line 76, in __lshift__
    self.set_upstream(other)
  File "/opt/anaconda3/lib/python3.8/site-packages/airflow/models/taskmixin.py", line 238, in set_upstream
    self._set_relatives(task_or_task_list, upstream=True, edge_modifier=edge_modifier)
  File "/opt/anaconda3/lib/python3.8/site-packages/airflow/models/taskmixin.py", line 193, in _set_relatives
    raise AirflowException(
airflow.exceptions.AirflowException: Tried to create relationships between tasks that don't have DAGs yet. Set the DAG for at least one task and try again: [<Task(PythonOperator): choosing_best_model>, <Task(PythonOperator): training_model_A>, <Task(PythonOperator): training_model_B>, <Task(PythonOperator): training_model_C>]
[2023-12-06T15:36:28.457+0700] {processor.py:755} WARNING - No viable dags retrieved from /Users/jacky/airflow/dags/my_dag.py
[2023-12-06T15:36:29.135+0700] {processor.py:175} INFO - Processing /Users/jacky/airflow/dags/my_dag.py took 0.755 seconds
[2023-12-06T15:38:45.886+0700] {processor.py:153} INFO - Started process (PID=76602) to work on /Users/jacky/airflow/dags/my_dag.py
[2023-12-06T15:38:45.888+0700] {processor.py:743} INFO - Processing file /Users/jacky/airflow/dags/my_dag.py for tasks to queue
[2023-12-06T15:38:45.889+0700] {logging_mixin.py:137} INFO - [2023-12-06T15:38:45.889+0700] {dagbag.py:538} INFO - Filling up the DagBag from /Users/jacky/airflow/dags/my_dag.py
[2023-12-06T15:38:45.958+0700] {logging_mixin.py:137} INFO - [2023-12-06T15:38:45.953+0700] {dagbag.py:343} ERROR - Failed to import: /Users/jacky/airflow/dags/my_dag.py
Traceback (most recent call last):
  File "/opt/anaconda3/lib/python3.8/site-packages/airflow/models/dagbag.py", line 339, in parse
    loader.exec_module(new_module)
  File "<frozen importlib._bootstrap_external>", line 783, in exec_module
  File "<frozen importlib._bootstrap>", line 219, in _call_with_frames_removed
  File "/Users/jacky/airflow/dags/my_dag.py", line 90, in <module>
    training_model_tasks >> choosing_best_model >> [accurate, inaccurate]
  File "/opt/anaconda3/lib/python3.8/site-packages/airflow/models/taskmixin.py", line 86, in __rrshift__
    self.__lshift__(other)
  File "/opt/anaconda3/lib/python3.8/site-packages/airflow/models/taskmixin.py", line 76, in __lshift__
    self.set_upstream(other)
  File "/opt/anaconda3/lib/python3.8/site-packages/airflow/models/taskmixin.py", line 238, in set_upstream
    self._set_relatives(task_or_task_list, upstream=True, edge_modifier=edge_modifier)
  File "/opt/anaconda3/lib/python3.8/site-packages/airflow/models/taskmixin.py", line 193, in _set_relatives
    raise AirflowException(
airflow.exceptions.AirflowException: Tried to create relationships between tasks that don't have DAGs yet. Set the DAG for at least one task and try again: [<Task(PythonOperator): choosing_best_model>, <Task(PythonOperator): training_model_A>, <Task(PythonOperator): training_model_B>, <Task(PythonOperator): training_model_C>]
[2023-12-06T15:38:45.958+0700] {processor.py:755} WARNING - No viable dags retrieved from /Users/jacky/airflow/dags/my_dag.py
[2023-12-06T15:38:46.678+0700] {processor.py:175} INFO - Processing /Users/jacky/airflow/dags/my_dag.py took 0.793 seconds
